Workbook

Sheet tree-scaling-viewport-w-specs_d
A1: Benchmark | B1: Mode | C1: Threads | D1: Samples | E1: Score | F1: Score Error (99.9%) | G1: Unit | H1: Param: MAX | I1: Param: ZOOM | J1: Param: viewport
A2: benchmark.TreeBenchmark.TreeScalingViewportBenchmark.search | B2: avgt | C2: 1 | D2: 5 | E2: 0.003448 | F2: 2.4e-05 | G2: ms/op | H2: 15 | I2: 30 | J2: ThreeHousesRoenne
A3: benchmark.TreeBenchmark.TreeScalingViewportBenchmark.search:depth | B3: avgt | C3: 1 | D3: 5 | E3: 35 | F3: NaN | G3: # | H3: 15 | I3: 30 | J3: ThreeHousesRoenne
A4: benchmark.TreeBenchmark.TreeScalingViewportBenchmark.search:depth_nonAccTest | B4: avgt | C4: 1 | D4: 5 | E4: 35 | F4: NaN | G4: # | H4: 15 | I4: 30 | J4: ThreeHousesRoenne
A5: benchmark.TreeBenchmark.TreeScalingViewportBenchmark.search:nodeCount | B5: avgt | C5: 1 | D5: 5 | E5: 661105 | F5: NaN | G5: # | H5: 15 | I5: 30 | J5: ThreeHousesRoenne
A6: benchmark.TreeBenchmark.TreeScalingViewportBenchmark.search:nodesVisited | B6: avgt | C6: 1 | D6: 5 | E6: 375 | F6: NaN | G6: # | H6: 15 | I6: 30 | J6: ThreeHousesRoenne
A7: benchmark.TreeBenchmark.TreeScalingViewportBenchmark.search | B7: avgt | C7: 1 | D7: 5 | E7: 4.96048 | F7: 0.444641 | G7: ms/op | H7: 15 | I7: 30 | J7: RoenneCity
A8: benchmark.TreeBenchmark.TreeScalingViewportBenchmark.search:depth | B8: avgt | C8: 1 | D8: 5 | E8: 35 | F8: NaN | G8: # | H8: 15 | I8: 30 | J8: RoenneCity
A9: benchmark.TreeBenchmark.TreeScalingViewportBenchmark.search:depth_nonAccTest | B9: avgt | C9: 1 | D9: 5 | E9: 35 | F9: NaN | G9: # | H9: 15 | I9: 30 | J9: RoenneCity
A10: benchmark.TreeBenchmark.TreeScalingViewportBenchmark.search:nodeCount | B10: avgt | C10: 1 | D10: 5 | E10: 661105 | F10: NaN | G10: # | H10: 15 | I10: 30 | J10: RoenneCity
A11: benchmark.TreeBenchmark.TreeScalingViewportBenchmark.search:nodesVisited | B11: avgt | C11: 1 | D11: 5 | E11: 45625 | F11: NaN | G11: # | H11: 15 | I11: 30 | J11: RoenneCity
A12: benchmark.TreeBenchmark.TreeScalingViewportBenchmark.search | B12: avgt | C12: 1 | D12: 5 | E12: 14.570232 | F12: 1.367552 | G12: ms/op | H12: 15 | I12: 30 | J12: GreaterRoenne
A13: benchmark.TreeBenchmark.TreeScalingViewportBenchmark.search:depth | B13: avgt | C13: 1 | D13: 5 | E13: 35 | F13: NaN | G13: # | H13: 15 | I13: 30 | J13: GreaterRoenne
A14: benchmark.TreeBenchmark.TreeScalingViewportBenchmark.search:depth_nonAccTest | B14: avgt | C14: 1 | D14: 5 | E14: 35 | F14: NaN | G14: # | H14: 15 | I14: 30 | J14: GreaterRoenne
A15: benchmark.TreeBenchmark.TreeScalingViewportBenchmark.search:nodeCount | B15: avgt | C15: 1 | D15: 5 | E15: 661105 | F15: NaN | G15: # | H15: 15 | I15: 30 | J15: GreaterRoenne
A16: benchmark.TreeBenchmark.TreeScalingViewportBenchmark.search:nodesVisited | B16: avgt | C16: 1 | D16: 5 | E16: 152895 | F16: NaN | G16: # | H16: 15 | I16: 30 | J16: GreaterRoenne
A17: benchmark.TreeBenchmark.TreeScalingViewportBenchmark.search | B17: avgt | C17: 1 | D17: 5 | E17: 20.507624 | F17: 1.978555 | G17: ms/op | H17: 15 | I17: 30 | J17: QuarterIslandCenterRoenne
A18: benchmark.TreeBenchmark.TreeScalingViewportBenchmark.search:depth | B18: avgt | C18: 1 | D18: 5 | E18: 35 | F18: NaN | G18: # | H18: 15 | I18: 30 | J18: QuarterIslandCenterRoenne
A19: benchmark.TreeBenchmark.TreeScalingViewportBenchmark.search:depth_nonAccTest | B19: avgt | C19: 1 | D19: 5 | E19: 35 | F19: NaN | G19: # | H19: 15 | I19: 30 | J19: QuarterIslandCenterRoenne
A20: benchmark.TreeBenchmark.TreeScalingViewportBenchmark.search:nodeCount | B20: avgt | C20: 1 | D20: 5 | E20: 661105 | F20: NaN | G20: # | H20: 15 | I20: 30 | J20: QuarterIslandCenterRoenne
A21: benchmark.TreeBenchmark.TreeScalingViewportBenchmark.search:nodesVisited | B21: avgt | C21: 1 | D21: 5 | E21: 228360 | F21: NaN | G21: # | H21: 15 | I21: 30 | J21: QuarterIslandCenterRoenne
A22: benchmark.TreeBenchmark.TreeScalingViewportBenchmark.search | B22: avgt | C22: 1 | D22: 5 | E22: 32.478005 | F22: 3.365875 | G22: ms/op | H22: 15 | I22: 30 | J22: HalfIslandBottom
A23: benchmark.TreeBenchmark.TreeScalingViewportBenchmark.search:depth | B23: avgt | C23: 1 | D23: 5 | E23: 35 | F23: NaN | G23: # | H23: 15 | I23: 30 | J23: HalfIslandBottom
A24: benchmark.TreeBenchmark.TreeScalingViewportBenchmark.search:depth_nonAccTest | B24: avgt | C24: 1 | D24: 5 | E24: 35 | F24: NaN | G24: # | H24: 15 | I24: 30 | J24: HalfIslandBottom
A25: benchmark.TreeBenchmark.TreeScalingViewportBenchmark.search:nodeCount | B25: avgt | C25: 1 | D25: 5 | E25: 661105 | F25: NaN | G25: # | H25: 15 | I25: 30 | J25: HalfIslandBottom
A26: benchmark.TreeBenchmark.TreeScalingViewportBenchmark.search:nodesVisited | B26: avgt | C26: 1 | D26: 5 | E26: 346545 | F26: NaN | G26: # | H26: 15 | I26: 30 | J26: HalfIslandBottom
A27: benchmark.TreeBenchmark.TreeScalingViewportBenchmark.search | B27: avgt | C27: 1 | D27: 5 | E27: 61.478993 | F27: 1.387248 | G27: ms/op | H27: 15 | I27: 30 | J27: FullIsland
A28: benchmark.TreeBenchmark.TreeScalingViewportBenchmark.search:depth | B28: avgt | C28: 1 | D28: 5 | E28: 35 | F28: NaN | G28: # | H28: 15 | I28: 30 | J28: FullIsland
A29: benchmark.TreeBenchmark.TreeScalingViewportBenchmark.search:depth_nonAccTest | B29: avgt | C29: 1 | D29: 5 | E29: 35 | F29: NaN | G29: # | H29: 15 | I29: 30 | J29: FullIsland
A30: benchmark.TreeBenchmark.TreeScalingViewportBenchmark.search:nodeCount | B30: avgt | C30: 1 | D30: 5 | E30: 661105 | F30: NaN | G30: # | H30: 15 | I30: 30 | J30: FullIsland
A31: benchmark.TreeBenchmark.TreeScalingViewportBenchmark.search:nodesVisited | B31: avgt | C31: 1 | D31: 5 | E31: 660785 | F31: NaN | G31: # | H31: 15 | I31: 30 | J31: FullIsland
A32: benchmark.TreeBenchmark.TreeScalingViewportBenchmark.search | B32: avgt | C32: 1 | D32: 5 | E32: 0.003074 | F32: 9.1e-05 | G32: ms/op | H32: 15 | I32: 30 | J32: DueoddeLighthouse
A33: benchmark.TreeBenchmark.TreeScalingViewportBenchmark.search:depth | B33: avgt | C33: 1 | D33: 5 | E33: 35 | F33: NaN | G33: # | H33: 15 | I33: 30 | J33: DueoddeLighthouse
A34: benchmark.TreeBenchmark.TreeScalingViewportBenchmark.search:depth_nonAccTest | B34: avgt | C34: 1 | D34: 5 | E34: 35 | F34: NaN | G34: # | H34: 15 | I34: 30 | J34: DueoddeLighthouse
A35: benchmark.TreeBenchmark.TreeScalingViewportBenchmark.search:nodeCount | B35: avgt | C35: 1 | D35: 5 | E35: 661105 | F35: NaN | G35: # | H35: 15 | I35: 30 | J35: DueoddeLighthouse
A36: benchmark.TreeBenchmark.TreeScalingViewportBenchmark.search:nodesVisited | B36: avgt | C36: 1 | D36: 5 | E36: 280 | F36: NaN | G36: # | H36: 15 | I36: 30 | J36: DueoddeLighthouse
A37: benchmark.TreeBenchmark.TreeScalingViewportBenchmark.search | B37: avgt | C37: 1 | D37: 5 | E37: 2.097894 | F37: 0.372841 | G37: ms/op | H37: 15 | I37: 30 | J37: DueoddeLighthouseGreaterArea
A38: benchmark.TreeBenchmark.TreeScalingViewportBenchmark.search:depth | B38: avgt | C38: 1 | D38: 5 | E38: 35 | F38: NaN | G38: # | H38: 15 | I38: 30 | J38: DueoddeLighthouseGreaterArea
A39: benchmark.TreeBenchmark.TreeScalingViewportBenchmark.search:depth_nonAccTest | B39: avgt | C39: 1 | D39: 5 | E39: 35 | F39: NaN | G39: # | H39: 15 | I39: 30 | J39: DueoddeLighthouseGreaterArea
A40: benchmark.TreeBenchmark.TreeScalingViewportBenchmark.search:nodeCount | B40: avgt | C40: 1 | D40: 5 | E40: 661105 | F40: NaN | G40: # | H40: 15 | I40: 30 | J40: DueoddeLighthouseGreaterArea
...

Sheet total-nodes_visited-nodes_ratio
A1: Viewport | B1: 15 | C1: 30 | D1: 45 | E1: 60 | F1: 90
A2: ThreeHousesRoenne | B2: ='tree-scaling-viewport-w-specs_d'!E6/'tree-scaling-viewport-w-specs_d'!E5 -> 0.00056723213 | C2: ='tree-scaling-viewport-w-specs_d'!E46/'tree-scaling-viewport-w-specs_d'!E45 -> 0.00077281023 | D2: ='tree-scaling-viewport-w-specs_d'!E86/'tree-scaling-viewport-w-specs_d'!E85 -> 0.0011390387 | E2: ='tree-scaling-viewport-w-specs_d'!E126/'tree-scaling-viewport-w-specs_d'!E125 -> 0.0010435251 | F2: ='tree-scaling-viewport-w-specs_d'!E166/'tree-scaling-viewport-w-specs_d'!E165 -> 0.0015705745
A3: RoenneCity | B3: ='tree-scaling-viewport-w-specs_d'!E11/'tree-scaling-viewport-w-specs_d'!E10 -> 0.069013243 | C3: ='tree-scaling-viewport-w-specs_d'!E51/'tree-scaling-viewport-w-specs_d'!E50 -> 0.069355608 | D3: ='tree-scaling-viewport-w-specs_d'!E91/'tree-scaling-viewport-w-specs_d'!E90 -> 0.071911307 | E3: ='tree-scaling-viewport-w-specs_d'!E131/'tree-scaling-viewport-w-specs_d'!E130 -> 0.072676474 | F3: ='tree-scaling-viewport-w-specs_d'!E171/'tree-scaling-viewport-w-specs_d'!E170 -> 0.077312798
A4: GreaterRoenne | B4: ='tree-scaling-viewport-w-specs_d'!E16/'tree-scaling-viewport-w-specs_d'!E15 -> 0.23127189 | C4: ='tree-scaling-viewport-w-specs_d'!E56/'tree-scaling-viewport-w-specs_d'!E55 -> 0.23501652 | D4: ='tree-scaling-viewport-w-specs_d'!E96/'tree-scaling-viewport-w-specs_d'!E95 -> 0.23474321 | E4: ='tree-scaling-viewport-w-specs_d'!E136/'tree-scaling-viewport-w-specs_d'!E135 -> 0.23957316 | F4: ='tree-scaling-viewport-w-specs_d'!E176/'tree-scaling-viewport-w-specs_d'!E175 -> 0.23817003
A5: QuarterIslandCenterRoenne | B5: ='tree-scaling-viewport-w-specs_d'!E21/'tree-scaling-viewport-w-specs_d'!E20 -> 0.34542168 | C5: ='tree-scaling-viewport-w-specs_d'!E61/'tree-scaling-viewport-w-specs_d'!E60 -> 0.34993505 | D5: ='tree-scaling-viewport-w-specs_d'!E101/'tree-scaling-viewport-w-specs_d'!E100 -> 0.35072266 | E5: ='tree-scaling-viewport-w-specs_d'!E141/'tree-scaling-viewport-w-specs_d'!E140 -> 0.35180261 | F5: ='tree-scaling-viewport-w-specs_d'!E181/'tree-scaling-viewport-w-specs_d'!E180 -> 0.35155538
A6: HalfIslandBottom | B6: ='tree-scaling-viewport-w-specs_d'!E26/'tree-scaling-viewport-w-specs_d'!E25 -> 0.52419056 | C6: ='tree-scaling-viewport-w-specs_d'!E66/'tree-scaling-viewport-w-specs_d'!E65 -> 0.52738543 | D6: ='tree-scaling-viewport-w-specs_d'!E106/'tree-scaling-viewport-w-specs_d'!E105 -> 0.5282355 | E6: ='tree-scaling-viewport-w-specs_d'!E146/'tree-scaling-viewport-w-specs_d'!E145 -> 0.53468879 | F6: ='tree-scaling-viewport-w-specs_d'!E186/'tree-scaling-viewport-w-specs_d'!E185 -> 0.53495795
A7: FullIsland | B7: ='tree-scaling-viewport-w-specs_d'!E31/'tree-scaling-viewport-w-specs_d'!E30 -> 0.99951596 | C7: ='tree-scaling-viewport-w-specs_d'!E71/'tree-scaling-viewport-w-specs_d'!E70 -> 0.9998849 | D7: ='tree-scaling-viewport-w-specs_d'!E111/'tree-scaling-viewport-w-specs_d'!E110 -> 0.99989875 | E7: ='tree-scaling-viewport-w-specs_d'!E151/'tree-scaling-viewport-w-specs_d'!E150 -> 0.99983169 | F7: ='tree-scaling-viewport-w-specs_d'!E191/'tree-scaling-viewport-w-specs_d'!E190 -> 0.99974668
A8: DueoddeLighthouse | B8: ='tree-scaling-viewport-w-specs_d'!E36/'tree-scaling-viewport-w-specs_d'!E35 -> 0.00042353333 | C8: ='tree-scaling-viewport-w-specs_d'!E76/'tree-scaling-viewport-w-specs_d'!E75 -> 0.00044395482 | D8: ='tree-scaling-viewport-w-specs_d'!E116/'tree-scaling-viewport-w-specs_d'!E115 -> 0.00080998304 | E8: ='tree-scaling-viewport-w-specs_d'!E156/'tree-scaling-viewport-w-specs_d'!E155 -> 0.0011108493 | F8: ='tree-scaling-viewport-w-specs_d'!E196/'tree-scaling-viewport-w-specs_d'!E195 -> 0.0012159287
A9: DueoddeLighthouseGreaterArea | B9: ='tree-scaling-viewport-w-specs_d'!E41/'tree-scaling-viewport-w-specs_d'!E40 -> 0.048123974 | C9: ='tree-scaling-viewport-w-specs_d'!E81/'tree-scaling-viewport-w-specs_d'!E80 -> 0.047667593 | D9: ='tree-scaling-viewport-w-specs_d'!E121/'tree-scaling-viewport-w-specs_d'!E120 -> 0.049282406 | E9: ='tree-scaling-viewport-w-specs_d'!E161/'tree-scaling-viewport-w-specs_d'!E160 -> 0.050998081 | F9: ='tree-scaling-viewport-w-specs_d'!E201/'tree-scaling-viewport-w-specs_d'!E200 -> 0.052538251

Sheet query-speed
A1: Max | B1: ThreeHousesRoenne | C1: RoenneCity | D1: GreaterRoenne | E1: QuarterIslandCenterRoenne | F1: HalfIslandBottom | G1: FullIsland | H1: DueoddeLighthouse | I1: DueoddeLighthouseGreaterArea
A2: 15 | B2: ='tree-scaling-viewport-w-specs_d'!E2 -> 0.003448 | C2: ='tree-scaling-viewport-w-specs_d'!E7 -> 4.96048 | D2: ='tree-scaling-viewport-w-specs_d'!E12 -> 14.570232 | E2: ='tree-scaling-viewport-w-specs_d'!E17 -> 20.507624 | F2: ='tree-scaling-viewport-w-specs_d'!E22 -> 32.478005 | G2: ='tree-scaling-viewport-w-specs_d'!E27 -> 61.478993 | H2: ='tree-scaling-viewport-w-specs_d'!E32 -> 0.003074 | I2: ='tree-scaling-viewport-w-specs_d'!E37 -> 2.097894
A3: 30 | B3: ='tree-scaling-viewport-w-specs_d'!E42 -> 0.004042 | C3: ='tree-scaling-viewport-w-specs_d'!E47 -> 3.389523 | D3: ='tree-scaling-viewport-w-specs_d'!E52 -> 13.448191 | E3: ='tree-scaling-viewport-w-specs_d'!E57 -> 19.439579 | F3: ='tree-scaling-viewport-w-specs_d'!E62 -> 31.407342 | G3: ='tree-scaling-viewport-w-specs_d'!E67 -> 56.348974 | H3: ='tree-scaling-viewport-w-specs_d'!E72 -> 0.002718 | I3: ='tree-scaling-viewport-w-specs_d'!E77 -> 2.098026
A4: 45 | B4: ='tree-scaling-viewport-w-specs_d'!E82 -> 0.005051 | C4: ='tree-scaling-viewport-w-specs_d'!E87 -> 3.650169 | D4: ='tree-scaling-viewport-w-specs_d'!E92 -> 14.163603 | E4: ='tree-scaling-viewport-w-specs_d'!E97 -> 20.180833 | F4: ='tree-scaling-viewport-w-specs_d'!E102 -> 30.482888 | G4: ='tree-scaling-viewport-w-specs_d'!E107 -> 57.589695 | H4: ='tree-scaling-viewport-w-specs_d'!E112 -> 0.004921 | I4: ='tree-scaling-viewport-w-specs_d'!E117 -> 2.202327
A5: 60 | B5: ='tree-scaling-viewport-w-specs_d'!E122 -> 0.006606 | C5: ='tree-scaling-viewport-w-specs_d'!E127 -> 3.687413 | D5: ='tree-scaling-viewport-w-specs_d'!E132 -> 13.816407 | E5: ='tree-scaling-viewport-w-specs_d'!E137 -> 19.924925 | F5: ='tree-scaling-viewport-w-specs_d'!E142 -> 31.543393 | G5: ='tree-scaling-viewport-w-specs_d'!E147 -> 56.195179 | H5: ='tree-scaling-viewport-w-specs_d'!E152 -> 0.006778 | I5: ='tree-scaling-viewport-w-specs_d'!E157 -> 2.256589
A6: 90 | B6: ='tree-scaling-viewport-w-specs_d'!E162 -> 0.006547 | C6: ='tree-scaling-viewport-w-specs_d'!E167 -> 3.905428 | D6: ='tree-scaling-viewport-w-specs_d'!E172 -> 13.932201 | E6: ='tree-scaling-viewport-w-specs_d'!E177 -> 19.699795 | F6: ='tree-scaling-viewport-w-specs_d'!E182 -> 30.372959 | G6: ='tree-scaling-viewport-w-specs_d'!E187 -> 56.518675 | H6: ='tree-scaling-viewport-w-specs_d'!E192 -> 0.006076 | I6: ='tree-scaling-viewport-w-specs_d'!E197 -> 2.33901
